<?xml version="1.0" ?>
<sdf version="1.10">
    <model name='carrinho' canonical_link='chassis'>
        <link name='chassis'>
            <pose>0 0 0.2 0 0 0</pose>
            <inertial> <!--inertial properties of the link mass, inertia matrix-->
                <mass>1.14395</mass>
                <inertia>
                    <ixx>0.103909</ixx>
                    <ixy>0</ixy>
                    <ixz>0</ixz>
                    <iyy>0.145854</iyy>
                    <iyz>0</iyz>
                    <izz>0.232603</izz>
                </inertia>
            </inertial>
            <visual name='visual'>
                <geometry>
                    <box>
                        <size>1.2 1.0 0.3</size>
                    </box>
                </geometry>
                <!--let's add color to our link-->
                <material>
                    <ambient>0.7 0.7 0.9 1</ambient>
                    <diffuse>0.7 0.7 0.9 1</diffuse>
                    <specular>0.7 0.7 0.9 1</specular>
                </material>
            </visual>
            <collision name='collision'>
                <geometry>
                    <box>
                        <size>1.2 1.0 0.3</size>
                    </box>
                </geometry>
            </collision>
        </link>
        <link name='left_wheel'>
            <pose relative_to="chassis">-0.4 0.6 0 -1.5707 0 0</pose>
            <inertial>
                <mass>1</mass>
                <inertia>
                    <ixx>0.013333</ixx>
                    <ixy>0</ixy>
                    <ixz>0</ixz>
                    <iyy>0.013333</iyy>
                    <iyz>0</iyz>
                    <izz>0.02</izz>
                </inertia>
            </inertial>
            <visual name='visual'>
                <geometry>
                    <cylinder>
                        <radius>0.2</radius>
                        <length>0.2</length>
                    </cylinder>
                </geometry>
                <material>
                    <ambient>0.5 0.5 0.7 1</ambient>
                    <diffuse>0.5 0.5 0.7 1</diffuse>
                    <specular>0.5 0.5 0.7 1</specular>
                </material>
            </visual>
            <collision name='collision'>
                <geometry>
                    <cylinder>
                        <radius>0.2</radius>
                        <length>0.2</length>
                    </cylinder>
                </geometry>
            </collision>
        </link>
        <link name='right_wheel'>
            <pose relative_to="chassis">-0.4 -0.6 0 -1.5707 0 0</pose> <!--angles are in radian-->
            <inertial>
                <mass>1</mass>
                <inertia>
                    <ixx>0.013333</ixx>
                    <ixy>0</ixy>
                    <ixz>0</ixz>
                    <iyy>0.013333</iyy>
                    <iyz>0</iyz>
                    <izz>0.02</izz>
                </inertia>
            </inertial>
            <visual name='visual'>
                <geometry>
                    <cylinder>
                        <radius>0.2</radius>
                        <length>0.2</length>
                    </cylinder>
                </geometry>
                <material>
                    <ambient>0.5 0.5 0.7 1</ambient>
                    <diffuse>0.5 0.5 0.7 1</diffuse>
                    <specular>0.5 0.5 0.7 1</specular>
                </material>
            </visual>
            <collision name='collision'>
                <geometry>
                    <cylinder>
                        <radius>0.2</radius>
                        <length>0.2</length>
                    </cylinder>
                </geometry>
            </collision>
        </link>
        <link name='back_left_wheel'>
            <pose relative_to="chassis">0.4 0.6 0 -1.5707 0 0</pose>
            <inertial>
                <mass>1</mass>
                <inertia>
                    <ixx>0.013333</ixx>
                    <ixy>0</ixy>
                    <ixz>0</ixz>
                    <iyy>0.013333</iyy>
                    <iyz>0</iyz>
                    <izz>0.02</izz>
                </inertia>
            </inertial>
            <visual name='visual'>
                <geometry>
                    <cylinder>
                        <radius>0.2</radius>
                        <length>0.2</length>
                    </cylinder>
                </geometry>
                <material>
                    <ambient>0.5 0.5 0.7 1</ambient>
                    <diffuse>0.5 0.5 0.7 1</diffuse>
                    <specular>0.5 0.5 0.7 1</specular>
                </material>
            </visual>
            <collision name='collision'>
                <geometry>
                    <cylinder>
                        <radius>0.2</radius>
                        <length>0.2</length>
                    </cylinder>
                </geometry>
            </collision>
        </link>
        <link name='back_right_wheel'>
            <pose relative_to="chassis">0.4 -0.6 0 -1.5707 0 0</pose> <!--angles are in radian-->
            <inertial>
                <mass>1</mass>
                <inertia>
                    <ixx>0.013333</ixx>
                    <ixy>0</ixy>
                    <ixz>0</ixz>
                    <iyy>0.013333</iyy>
                    <iyz>0</iyz>
                    <izz>0.02</izz>
                </inertia>
            </inertial>
            <visual name='visual'>
                <geometry>
                    <cylinder>
                        <radius>0.2</radius>
                        <length>0.2</length>
                    </cylinder>
                </geometry>
                <material>
                    <ambient>0.5 0.5 0.7 1</ambient>
                    <diffuse>0.5 0.5 0.7 1</diffuse>
                    <specular>0.5 0.5 0.7 1</specular>
                </material>
            </visual>
            <collision name='collision'>
                <geometry>
                    <cylinder>
                        <radius>0.2</radius>
                        <length>0.2</length>
                    </cylinder>
                </geometry>
            </collision>
        </link>        
        <joint name='left_wheel_joint' type='revolute'>
            <pose relative_to='left_wheel'/>
            <parent>chassis</parent>
            <child>left_wheel</child>
            <axis>
                <xyz expressed_in="chassis">0 1 0</xyz> <!--can be defined as any frame or even arbitrary frames-->
                <limit>
                    <lower>-1.79769e+308</lower>    <!--negative infinity-->
                    <upper>1.79769e+308</upper>     <!--positive infinity-->
                </limit>
            </axis>
        </joint>
        <joint name='right_wheel_joint' type='revolute'>
            <pose relative_to='right_wheel'/>
            <parent>chassis</parent>
            <child>right_wheel</child>
            <axis>
                <xyz expressed_in="chassis">0 1 0</xyz>
                <limit>
                    <lower>-1.79769e+308</lower>    <!--negative infinity-->
                    <upper>1.79769e+308</upper>     <!--positive infinity-->
                </limit>
            </axis>
        </joint>
        <joint name='back_left_wheel_joint' type='revolute'>
            <pose relative_to='back_left_wheel'/>
            <parent>chassis</parent>
            <child>back_left_wheel</child>
            <axis>
                <xyz expressed_in="chassis">0 1 0</xyz> <!--can be defined as any frame or even arbitrary frames-->
                <limit>
                    <lower>-1.79769e+308</lower>    <!--negative infinity-->
                    <upper>1.79769e+308</upper>     <!--positive infinity-->
                </limit>
            </axis>
        </joint>
        <joint name='back_right_wheel_joint' type='revolute'>
            <pose relative_to='back_right_wheel'/>
            <parent>chassis</parent>
            <child>back_right_wheel</child>
            <axis>
                <xyz expressed_in="chassis">0 1 0</xyz>
                <limit>
                    <lower>-1.79769e+308</lower>    <!--negative infinity-->
                    <upper>1.79769e+308</upper>     <!--positive infinity-->
                </limit>
            </axis>
        </joint>
    </model>
</sdf>